[2024-05-22T19:29:25.948+0000] {local_task_job_runner.py:120} INFO - ::group::Pre task execution logs
[2024-05-22T19:29:25.964+0000] {taskinstance.py:2076} INFO - Dependencies all met for dep_context=non-requeueable deps ti=<TaskInstance: disney_api.processing_data manual__2024-05-22T19:24:22.802280+00:00 [queued]>
[2024-05-22T19:29:25.972+0000] {taskinstance.py:2076} INFO - Dependencies all met for dep_context=requeueable deps ti=<TaskInstance: disney_api.processing_data manual__2024-05-22T19:24:22.802280+00:00 [queued]>
[2024-05-22T19:29:25.973+0000] {taskinstance.py:2306} INFO - Starting attempt 2 of 2
[2024-05-22T19:29:25.983+0000] {taskinstance.py:2330} INFO - Executing <Task(PythonOperator): processing_data> on 2024-05-22 19:24:22.802280+00:00
[2024-05-22T19:29:25.991+0000] {standard_task_runner.py:90} INFO - Running: ['***', 'tasks', 'run', 'disney_api', 'processing_data', 'manual__2024-05-22T19:24:22.802280+00:00', '--job-id', '31', '--raw', '--subdir', 'DAGS_FOLDER/disney_api_dag.py', '--cfg-path', '/tmp/tmp9lp36jt7']
[2024-05-22T19:29:25.993+0000] {logging_mixin.py:188} WARNING - /home/***/.local/lib/python3.12/site-packages/***/task/task_runner/standard_task_runner.py:61 DeprecationWarning: This process (pid=3773) is multi-threaded, use of fork() may lead to deadlocks in the child.
[2024-05-22T19:29:25.993+0000] {standard_task_runner.py:91} INFO - Job 31: Subtask processing_data
[2024-05-22T19:29:25.994+0000] {standard_task_runner.py:63} INFO - Started process 3775 to run task
[2024-05-22T19:29:26.032+0000] {task_command.py:426} INFO - Running <TaskInstance: disney_api.processing_data manual__2024-05-22T19:24:22.802280+00:00 [running]> on host b4db1197dafa
[2024-05-22T19:29:26.096+0000] {taskinstance.py:2648} INFO - Exporting env vars: AIRFLOW_CTX_DAG_EMAIL='marcelo.vicente@gmail.com' AIRFLOW_CTX_DAG_OWNER='***' AIRFLOW_CTX_DAG_ID='disney_api' AIRFLOW_CTX_TASK_ID='processing_data' AIRFLOW_CTX_EXECUTION_DATE='2024-05-22T19:24:22.802280+00:00' AIRFLOW_CTX_TRY_NUMBER='2' AIRFLOW_CTX_DAG_RUN_ID='manual__2024-05-22T19:24:22.802280+00:00'
[2024-05-22T19:29:26.098+0000] {taskinstance.py:430} INFO - ::endgroup::
[2024-05-22T19:29:26.164+0000] {logging_mixin.py:188} INFO - <class 'pandas.core.frame.DataFrame'>
RangeIndex: 50 entries, 0 to 49
Data columns (total 15 columns):
 #   Column           Non-Null Count  Dtype 
---  ------           --------------  ----- 
 0   _id              50 non-null     int64 
 1   films            50 non-null     object
 2   shortFilms       50 non-null     object
 3   tvShows          50 non-null     object
 4   videoGames       50 non-null     object
 5   parkAttractions  50 non-null     object
 6   allies           50 non-null     object
 7   enemies          50 non-null     object
 8   sourceUrl        50 non-null     object
 9   name             50 non-null     object
 10  imageUrl         48 non-null     object
 11  createdAt        50 non-null     object
 12  updatedAt        50 non-null     object
 13  url              50 non-null     object
 14  __v              50 non-null     int64 
dtypes: int64(2), object(13)
memory usage: 6.0+ KB
[2024-05-22T19:29:26.165+0000] {logging_mixin.py:188} INFO - AQUI 3:  50
[2024-05-22T19:29:26.166+0000] {taskinstance.py:441} INFO - ::group::Post task execution logs
[2024-05-22T19:29:26.167+0000] {taskinstance.py:2905} ERROR - Task failed with exception
Traceback (most recent call last):
  File "/home/airflow/.local/lib/python3.12/site-packages/airflow/models/taskinstance.py", line 465, in _execute_task
    result = _execute_callable(context=context, **execute_callable_kwargs)
             ^^^^^^^^^^^^^^^^^^^^^^^^^^^^^^^^^^^^^^^^^^^^^^^^^^^^^^^^^^^^^
  File "/home/airflow/.local/lib/python3.12/site-packages/airflow/models/taskinstance.py", line 432, in _execute_callable
    return execute_callable(context=context, **execute_callable_kwargs)
           ^^^^^^^^^^^^^^^^^^^^^^^^^^^^^^^^^^^^^^^^^^^^^^^^^^^^^^^^^^^^
  File "/home/airflow/.local/lib/python3.12/site-packages/airflow/models/baseoperator.py", line 400, in wrapper
    return func(self, *args, **kwargs)
           ^^^^^^^^^^^^^^^^^^^^^^^^^^^
  File "/home/airflow/.local/lib/python3.12/site-packages/airflow/operators/python.py", line 235, in execute
    return_value = self.execute_callable()
                   ^^^^^^^^^^^^^^^^^^^^^^^
  File "/home/airflow/.local/lib/python3.12/site-packages/airflow/operators/python.py", line 252, in execute_callable
    return self.python_callable(*self.op_args, **self.op_kwargs)
           ^^^^^^^^^^^^^^^^^^^^^^^^^^^^^^^^^^^^^^^^^^^^^^^^^^^^^
  File "/opt/airflow/dags/disney_api_dag.py", line 43, in processing_data
    df_01 = pd.json_normalize(disney_data)
                              ^^^^^^^^^^^
NameError: name 'disney_data' is not defined
[2024-05-22T19:29:26.181+0000] {taskinstance.py:1206} INFO - Marking task as FAILED. dag_id=disney_api, task_id=processing_data, run_id=manual__2024-05-22T19:24:22.802280+00:00, execution_date=20240522T192422, start_date=20240522T192925, end_date=20240522T192926
[2024-05-22T19:29:26.193+0000] {standard_task_runner.py:110} ERROR - Failed to execute job 31 for task processing_data (name 'disney_data' is not defined; 3775)
[2024-05-22T19:29:26.209+0000] {local_task_job_runner.py:240} INFO - Task exited with return code 1
[2024-05-22T19:29:26.222+0000] {taskinstance.py:3498} INFO - 0 downstream tasks scheduled from follow-on schedule check
[2024-05-22T19:29:26.225+0000] {local_task_job_runner.py:222} INFO - ::endgroup::
