[2024-05-22T18:55:22.359+0000] {local_task_job_runner.py:120} INFO - ::group::Pre task execution logs
[2024-05-22T18:55:22.374+0000] {taskinstance.py:2076} INFO - Dependencies all met for dep_context=non-requeueable deps ti=<TaskInstance: disney_api.processing_data manual__2024-05-22T18:55:16.771752+00:00 [queued]>
[2024-05-22T18:55:22.381+0000] {taskinstance.py:2076} INFO - Dependencies all met for dep_context=requeueable deps ti=<TaskInstance: disney_api.processing_data manual__2024-05-22T18:55:16.771752+00:00 [queued]>
[2024-05-22T18:55:22.382+0000] {taskinstance.py:2306} INFO - Starting attempt 1 of 1
[2024-05-22T18:55:22.393+0000] {taskinstance.py:2330} INFO - Executing <Task(PythonOperator): processing_data> on 2024-05-22 18:55:16.771752+00:00
[2024-05-22T18:55:22.398+0000] {standard_task_runner.py:90} INFO - Running: ['***', 'tasks', 'run', 'disney_api', 'processing_data', 'manual__2024-05-22T18:55:16.771752+00:00', '--job-id', '19', '--raw', '--subdir', 'DAGS_FOLDER/disney_api_dag.py', '--cfg-path', '/tmp/tmpvo2xp1e3']
[2024-05-22T18:55:22.400+0000] {standard_task_runner.py:91} INFO - Job 19: Subtask processing_data
[2024-05-22T18:55:22.401+0000] {logging_mixin.py:188} WARNING - /home/***/.local/lib/python3.12/site-packages/***/task/task_runner/standard_task_runner.py:61 DeprecationWarning: This process (pid=2840) is multi-threaded, use of fork() may lead to deadlocks in the child.
[2024-05-22T18:55:22.402+0000] {standard_task_runner.py:63} INFO - Started process 2842 to run task
[2024-05-22T18:55:22.437+0000] {task_command.py:426} INFO - Running <TaskInstance: disney_api.processing_data manual__2024-05-22T18:55:16.771752+00:00 [running]> on host b4db1197dafa
[2024-05-22T18:55:22.502+0000] {taskinstance.py:2648} INFO - Exporting env vars: AIRFLOW_CTX_DAG_EMAIL='marcelo.vicente@gmail.com' AIRFLOW_CTX_DAG_OWNER='***' AIRFLOW_CTX_DAG_ID='disney_api' AIRFLOW_CTX_TASK_ID='processing_data' AIRFLOW_CTX_EXECUTION_DATE='2024-05-22T18:55:16.771752+00:00' AIRFLOW_CTX_TRY_NUMBER='1' AIRFLOW_CTX_DAG_RUN_ID='manual__2024-05-22T18:55:16.771752+00:00'
[2024-05-22T18:55:22.503+0000] {taskinstance.py:430} INFO - ::endgroup::
[2024-05-22T18:55:22.546+0000] {logging_mixin.py:188} INFO - <class 'pandas.core.frame.DataFrame'>
RangeIndex: 15 entries, 0 to 14
Empty DataFrame
[2024-05-22T18:55:22.548+0000] {logging_mixin.py:188} INFO - <class 'pandas.core.frame.DataFrame'>
RangeIndex: 15 entries, 0 to 14
Empty DataFrame
[2024-05-22T18:55:22.550+0000] {logging_mixin.py:188} INFO - Dados:  Empty DataFrame
Columns: []
Index: [0, 1, 2, 3, 4]
[2024-05-22T18:55:22.562+0000] {base_aws.py:582} WARNING - Unable to find AWS Connection ID 'aws_default', switching to empty.
[2024-05-22T18:55:22.563+0000] {base_aws.py:162} INFO - No connection ID provided. Fallback on boto3 credential strategy (region_name=None). See: https://boto3.amazonaws.com/v1/documentation/api/latest/guide/configuration.html
[2024-05-22T18:55:23.116+0000] {taskinstance.py:441} INFO - ::group::Post task execution logs
[2024-05-22T18:55:23.117+0000] {taskinstance.py:2905} ERROR - Task failed with exception
Traceback (most recent call last):
  File "/home/airflow/.local/lib/python3.12/site-packages/airflow/models/taskinstance.py", line 465, in _execute_task
    result = _execute_callable(context=context, **execute_callable_kwargs)
             ^^^^^^^^^^^^^^^^^^^^^^^^^^^^^^^^^^^^^^^^^^^^^^^^^^^^^^^^^^^^^
  File "/home/airflow/.local/lib/python3.12/site-packages/airflow/models/taskinstance.py", line 432, in _execute_callable
    return execute_callable(context=context, **execute_callable_kwargs)
           ^^^^^^^^^^^^^^^^^^^^^^^^^^^^^^^^^^^^^^^^^^^^^^^^^^^^^^^^^^^^
  File "/home/airflow/.local/lib/python3.12/site-packages/airflow/models/baseoperator.py", line 400, in wrapper
    return func(self, *args, **kwargs)
           ^^^^^^^^^^^^^^^^^^^^^^^^^^^
  File "/home/airflow/.local/lib/python3.12/site-packages/airflow/operators/python.py", line 235, in execute
    return_value = self.execute_callable()
                   ^^^^^^^^^^^^^^^^^^^^^^^
  File "/home/airflow/.local/lib/python3.12/site-packages/airflow/operators/python.py", line 252, in execute_callable
    return self.python_callable(*self.op_args, **self.op_kwargs)
           ^^^^^^^^^^^^^^^^^^^^^^^^^^^^^^^^^^^^^^^^^^^^^^^^^^^^^
  File "/opt/airflow/dags/disney_api_dag.py", line 53, in processing_data
    s3.load_bytes(bytes_data=out_buffer.getvalue(), bucket_name=s3_bucket, replace=True, key=s3_key)
  File "/home/airflow/.local/lib/python3.12/site-packages/airflow/providers/amazon/aws/hooks/s3.py", line 135, in wrapper
    return func(*bound_args.args, **bound_args.kwargs)
           ^^^^^^^^^^^^^^^^^^^^^^^^^^^^^^^^^^^^^^^^^^^
  File "/home/airflow/.local/lib/python3.12/site-packages/airflow/providers/amazon/aws/hooks/s3.py", line 89, in wrapper
    return func(*bound_args.args, **bound_args.kwargs)
           ^^^^^^^^^^^^^^^^^^^^^^^^^^^^^^^^^^^^^^^^^^^
  File "/home/airflow/.local/lib/python3.12/site-packages/airflow/providers/amazon/aws/hooks/s3.py", line 1182, in load_bytes
    self._upload_file_obj(f, key, bucket_name, replace, encrypt, acl_policy)
  File "/home/airflow/.local/lib/python3.12/site-packages/airflow/providers/amazon/aws/hooks/s3.py", line 1232, in _upload_file_obj
    client.upload_fileobj(
  File "/home/airflow/.local/lib/python3.12/site-packages/boto3/s3/inject.py", line 642, in upload_fileobj
    return future.result()
           ^^^^^^^^^^^^^^^
  File "/home/airflow/.local/lib/python3.12/site-packages/s3transfer/futures.py", line 103, in result
    return self._coordinator.result()
           ^^^^^^^^^^^^^^^^^^^^^^^^^^
  File "/home/airflow/.local/lib/python3.12/site-packages/s3transfer/futures.py", line 266, in result
    raise self._exception
  File "/home/airflow/.local/lib/python3.12/site-packages/s3transfer/tasks.py", line 139, in __call__
    return self._execute_main(kwargs)
           ^^^^^^^^^^^^^^^^^^^^^^^^^^
  File "/home/airflow/.local/lib/python3.12/site-packages/s3transfer/tasks.py", line 162, in _execute_main
    return_value = self._main(**kwargs)
                   ^^^^^^^^^^^^^^^^^^^^
  File "/home/airflow/.local/lib/python3.12/site-packages/s3transfer/upload.py", line 764, in _main
    client.put_object(Bucket=bucket, Key=key, Body=body, **extra_args)
  File "/home/airflow/.local/lib/python3.12/site-packages/botocore/client.py", line 553, in _api_call
    return self._make_api_call(operation_name, kwargs)
           ^^^^^^^^^^^^^^^^^^^^^^^^^^^^^^^^^^^^^^^^^^^
  File "/home/airflow/.local/lib/python3.12/site-packages/botocore/client.py", line 989, in _make_api_call
    http, parsed_response = self._make_request(
                            ^^^^^^^^^^^^^^^^^^^
  File "/home/airflow/.local/lib/python3.12/site-packages/botocore/client.py", line 1015, in _make_request
    return self._endpoint.make_request(operation_model, request_dict)
           ^^^^^^^^^^^^^^^^^^^^^^^^^^^^^^^^^^^^^^^^^^^^^^^^^^^^^^^^^^
  File "/home/airflow/.local/lib/python3.12/site-packages/botocore/endpoint.py", line 119, in make_request
    return self._send_request(request_dict, operation_model)
           ^^^^^^^^^^^^^^^^^^^^^^^^^^^^^^^^^^^^^^^^^^^^^^^^^
  File "/home/airflow/.local/lib/python3.12/site-packages/botocore/endpoint.py", line 198, in _send_request
    request = self.create_request(request_dict, operation_model)
              ^^^^^^^^^^^^^^^^^^^^^^^^^^^^^^^^^^^^^^^^^^^^^^^^^^
  File "/home/airflow/.local/lib/python3.12/site-packages/botocore/endpoint.py", line 134, in create_request
    self._event_emitter.emit(
  File "/home/airflow/.local/lib/python3.12/site-packages/botocore/hooks.py", line 412, in emit
    return self._emitter.emit(aliased_event_name, **kwargs)
           ^^^^^^^^^^^^^^^^^^^^^^^^^^^^^^^^^^^^^^^^^^^^^^^^
  File "/home/airflow/.local/lib/python3.12/site-packages/botocore/hooks.py", line 256, in emit
    return self._emit(event_name, kwargs)
           ^^^^^^^^^^^^^^^^^^^^^^^^^^^^^^
  File "/home/airflow/.local/lib/python3.12/site-packages/botocore/hooks.py", line 239, in _emit
    response = handler(**kwargs)
               ^^^^^^^^^^^^^^^^^
  File "/home/airflow/.local/lib/python3.12/site-packages/botocore/signers.py", line 105, in handler
    return self.sign(operation_name, request)
           ^^^^^^^^^^^^^^^^^^^^^^^^^^^^^^^^^^
  File "/home/airflow/.local/lib/python3.12/site-packages/botocore/signers.py", line 195, in sign
    auth.add_auth(request)
  File "/home/airflow/.local/lib/python3.12/site-packages/botocore/auth.py", line 418, in add_auth
    raise NoCredentialsError()
botocore.exceptions.NoCredentialsError: Unable to locate credentials
[2024-05-22T18:55:23.128+0000] {taskinstance.py:1206} INFO - Marking task as FAILED. dag_id=disney_api, task_id=processing_data, run_id=manual__2024-05-22T18:55:16.771752+00:00, execution_date=20240522T185516, start_date=20240522T185522, end_date=20240522T185523
[2024-05-22T18:55:23.138+0000] {standard_task_runner.py:110} ERROR - Failed to execute job 19 for task processing_data (Unable to locate credentials; 2842)
[2024-05-22T18:55:23.180+0000] {local_task_job_runner.py:240} INFO - Task exited with return code 1
[2024-05-22T18:55:23.196+0000] {taskinstance.py:3498} INFO - 0 downstream tasks scheduled from follow-on schedule check
[2024-05-22T18:55:23.199+0000] {local_task_job_runner.py:222} INFO - ::endgroup::
